Workbook

Sheet PAINEL
A1: PAINEL DE GESTAO DO SAC
A3: Mes de referencia (dia 1 do mes): | B3: 46266 | D3: Preencha esta celula para filtrar os indicadores abaixo pelo mes desejado.
A5: INDICADORES DO MES
A6: Indicador | B6: Realizado | C6: Meta | D6: Status | E6: Observacao
A7: Chamados recebidos | B7: =COUNTIFS(SAC!$B$3:$B$400,">="&$B$3,SAC!$B$3:$B$400,"<"&EDATE($B$3,1)) -> 0 | C7: 20 | D7: =IF(B7<=C7,"Verde",IF(B7<=C7*1.2,"Amarelo","Vermelho")) -> Verde
A8: Chamados resolvidos | B8: =COUNTIFS(SAC!$N$3:$N$400,">="&$B$3,SAC!$N$3:$N$400,"<"&EDATE($B$3,1)) -> 0 | C8: 18 | D8: =IF(B8>=C8,"Verde",IF(B8>=C8*0.8,"Amarelo","Vermelho")) -> Vermelho
A9: Chamados pendentes (em aberto hoje) | B9: =COUNTIFS(SAC!$L$3:$L$400,"<>Resolvido",SAC!$L$3:$L$400,"<>Cancelado",SAC!$L$3:$L$400,"<>") -> 0 | C9: 5 | D9: =IF(B9<=C9,"Verde",IF(B9<=C9*1.2,"Amarelo","Vermelho")) -> Verde
A10: Tempo medio de resposta (dias) | B10: =IFERROR(AVERAGEIFS(SAC!$O$3:$O$400,SAC!$B$3:$B$400,">="&$B$3,SAC!$B$3:$B$400,"<"&EDATE($B$3,1)),0) -> 0.0 | C10: 1 | D10: =IF(B10<=C10,"Verde",IF(B10<=C10*1.2,"Amarelo","Vermelho")) -> Verde
A11: Tempo medio de solucao (dias) | B11: =IFERROR(AVERAGEIFS(SAC!$P$3:$P$400,SAC!$B$3:$B$400,">="&$B$3,SAC!$B$3:$B$400,"<"&EDATE($B$3,1)),0) -> 0.0 | C11: 5 | D11: =IF(B11<=C11,"Verde",IF(B11<=C11*1.2,"Amarelo","Vermelho")) -> Verde
A12: Reclamacoes | B12: =COUNTIFS(SAC!$H$3:$H$400,"Reclamacao",SAC!$B$3:$B$400,">="&$B$3,SAC!$B$3:$B$400,"<"&EDATE($B$3,1)) -> 0 | C12: 5 | D12: =IF(B12<=C12,"Verde",IF(B12<=C12*1.2,"Amarelo","Vermelho")) -> Verde
A13: Trocas | B13: =COUNTIFS(SAC!$H$3:$H$400,"Troca",SAC!$B$3:$B$400,">="&$B$3,SAC!$B$3:$B$400,"<"&EDATE($B$3,1)) -> 0 | C13: 5 | D13: =IF(B13<=C13,"Verde",IF(B13<=C13*1.2,"Amarelo","Vermelho")) -> Verde
A14: Avarias | B14: =COUNTIFS(SAC!$H$3:$H$400,"Avaria",SAC!$B$3:$B$400,">="&$B$3,SAC!$B$3:$B$400,"<"&EDATE($B$3,1)) -> 0 | C14: 4 | D14: =IF(B14<=C14,"Verde",IF(B14<=C14*1.2,"Amarelo","Vermelho")) -> Verde
A15: Pecas faltantes | B15: =COUNTIFS(SAC!$H$3:$H$400,"Peca faltante",SAC!$B$3:$B$400,">="&$B$3,SAC!$B$3:$B$400,"<"&EDATE($B$3,1)) -> 0 | C15: 4 | D15: =IF(B15<=C15,"Verde",IF(B15<=C15*1.2,"Amarelo","Vermelho")) -> Verde
A16: Satisfacao media (1-5) | B16: =IFERROR(AVERAGEIFS(SAC!$R$3:$R$400,SAC!$B$3:$B$400,">="&$B$3,SAC!$B$3:$B$400,"<"&EDATE($B$3,1)),0) -> 0.0 | C16: 4.5 | D16: =IF(B16>=C16,"Verde",IF(B16>=C16*0.8,"Amarelo","Vermelho")) -> Vermelho
A17: Pos-vendas realizados | B17: =COUNTIFS('POS-VENDA'!$A$3:$A$150,">="&$B$3,'POS-VENDA'!$A$3:$A$150,"<"&EDATE($B$3,1)) -> 0 | C17: 15 | D17: =IF(B17>=C17,"Verde",IF(B17>=C17*0.8,"Amarelo","Vermelho")) -> Vermelho
A18: Recompras no mes | B18: =COUNTIFS('CLIENTES E RECOMPRA'!$G$3:$G$150,"Sim",'CLIENTES E RECOMPRA'!$H$3:$H$150,">="&$B$3,'CLIENTES E RECOMPRA'!$H$3:$H$150,"<"&EDATE($B$3,1)) -> 0 | C18: 3 | D18: =IF(B18>=C18,"Verde",IF(B18>=C18*0.8,"Amarelo","Vermelho")) -> Vermelho
A19: Custo gerado pelo SAC (R$) | B19: =SUMIFS(SAC!$Q$3:$Q$400,SAC!$B$3:$B$400,">="&$B$3,SAC!$B$3:$B$400,"<"&EDATE($B$3,1)) -> R$ 0.00 | C19: 2000 | D19: =IF(B19<=C19,"Verde",IF(B19<=C19*1.2,"Amarelo","Vermelho")) -> Verde
A20: NC canais externos (ML+Instagram+Lojista) no mes | B20: =COUNTIFS('NC CANAIS'!$A$2:$A$300,">="&$B$3,'NC CANAIS'!$A$2:$A$300,"<"&EDATE($B$3,1)) -> 1 | C20: 6 | D20: =IF(B20<=C20,"Verde",IF(B20<=C20*1.2,"Amarelo","Vermelho")) -> Verde
A21: Custo NC canais externos no mes (R$) | B21: =SUMIFS('NC CANAIS'!$P$2:$P$300,'NC CANAIS'!$A$2:$A$300,">="&$B$3,'NC CANAIS'!$A$2:$A$300,"<"&EDATE($B$3,1)) -> R$ 250.00 | C21: 1500 | D21: =IF(B21<=C21,"Verde",IF(B21<=C21*1.2,"Amarelo","Vermelho")) -> Verde
A22: Coluna Meta (amarela): edite livremente com a meta desejada de cada indicador.
A23: Verde = dentro da meta | Amarelo = ate 20% fora da meta | Vermelho = mais de 20% fora da meta.
A24: Os indicadores puxam automaticamente das abas SAC, POS-VENDA e CLIENTES E RECOMPRA - basta preencher os chamados la.
A26: PRIORIDADES EM ABERTO (o que resolver primeiro)
A27: ID | B27: Cliente | C27: Tipo | D27: Prioridade | E27: Dias em aberto
A28: Use um filtro/classificacao na aba SAC (coluna Prioridade e Status) para listar aqui os chamados em aberto por urgencia.

Sheet INDICADORES
A1: INDICADORES DE NAO CONFORMIDADE
A2: Mes de referencia: | B2: =PAINEL!$B$3 -> September/2026
A4: CHAMADOS POR CATEGORIA (NAO CONFORMIDADE)
A5: Categoria do problema | B5: Qtd no mes | C5: Qtd total (historico) | D5: Custo total (R$)
A6: Acabamento | B6: =COUNTIFS(SAC!$J$3:$J$400,$A6,SAC!$B$3:$B$400,">="&PAINEL!$B$3,SAC!$B$3:$B$400,"<"&EDATE(PAINEL!$B$3,1)) -> 0 | C6: =COUNTIFS(SAC!$J$3:$J$400,$A6) -> 0 | D6: =SUMIFS(SAC!$Q$3:$Q$400,SAC!$J$3:$J$400,$A6) -> R$ 0.00
A7: Embalagem | B7: =COUNTIFS(SAC!$J$3:$J$400,$A7,SAC!$B$3:$B$400,">="&PAINEL!$B$3,SAC!$B$3:$B$400,"<"&EDATE(PAINEL!$B$3,1)) -> 0 | C7: =COUNTIFS(SAC!$J$3:$J$400,$A7) -> 0 | D7: =SUMIFS(SAC!$Q$3:$Q$400,SAC!$J$3:$J$400,$A7) -> R$ 0.00
A8: Material | B8: =COUNTIFS(SAC!$J$3:$J$400,$A8,SAC!$B$3:$B$400,">="&PAINEL!$B$3,SAC!$B$3:$B$400,"<"&EDATE(PAINEL!$B$3,1)) -> 0 | C8: =COUNTIFS(SAC!$J$3:$J$400,$A8) -> 0 | D8: =SUMIFS(SAC!$Q$3:$Q$400,SAC!$J$3:$J$400,$A8) -> R$ 0.00
A9: Hidraulica | B9: =COUNTIFS(SAC!$J$3:$J$400,$A9,SAC!$B$3:$B$400,">="&PAINEL!$B$3,SAC!$B$3:$B$400,"<"&EDATE(PAINEL!$B$3,1)) -> 0 | C9: =COUNTIFS(SAC!$J$3:$J$400,$A9) -> 0 | D9: =SUMIFS(SAC!$Q$3:$Q$400,SAC!$J$3:$J$400,$A9) -> R$ 0.00
A10: Costura | B10: =COUNTIFS(SAC!$J$3:$J$400,$A10,SAC!$B$3:$B$400,">="&PAINEL!$B$3,SAC!$B$3:$B$400,"<"&EDATE(PAINEL!$B$3,1)) -> 0 | C10: =COUNTIFS(SAC!$J$3:$J$400,$A10) -> 0 | D10: =SUMIFS(SAC!$Q$3:$Q$400,SAC!$J$3:$J$400,$A10) -> R$ 0.00
A11: Montagem | B11: =COUNTIFS(SAC!$J$3:$J$400,$A11,SAC!$B$3:$B$400,">="&PAINEL!$B$3,SAC!$B$3:$B$400,"<"&EDATE(PAINEL!$B$3,1)) -> 0 | C11: =COUNTIFS(SAC!$J$3:$J$400,$A11) -> 0 | D11: =SUMIFS(SAC!$Q$3:$Q$400,SAC!$J$3:$J$400,$A11) -> R$ 0.00
A12: Peca faltante | B12: =COUNTIFS(SAC!$J$3:$J$400,$A12,SAC!$B$3:$B$400,">="&PAINEL!$B$3,SAC!$B$3:$B$400,"<"&EDATE(PAINEL!$B$3,1)) -> 0 | C12: =COUNTIFS(SAC!$J$3:$J$400,$A12) -> 0 | D12: =SUMIFS(SAC!$Q$3:$Q$400,SAC!$J$3:$J$400,$A12) -> R$ 0.00
A13: Peca quebrada | B13: =COUNTIFS(SAC!$J$3:$J$400,$A13,SAC!$B$3:$B$400,">="&PAINEL!$B$3,SAC!$B$3:$B$400,"<"&EDATE(PAINEL!$B$3,1)) -> 0 | C13: =COUNTIFS(SAC!$J$3:$J$400,$A13) -> 0 | D13: =SUMIFS(SAC!$Q$3:$Q$400,SAC!$J$3:$J$400,$A13) -> R$ 0.00
A14: Dificuldade de montagem | B14: =COUNTIFS(SAC!$J$3:$J$400,$A14,SAC!$B$3:$B$400,">="&PAINEL!$B$3,SAC!$B$3:$B$400,"<"&EDATE(PAINEL!$B$3,1)) -> 0 | C14: =COUNTIFS(SAC!$J$3:$J$400,$A14) -> 0 | D14: =SUMIFS(SAC!$Q$3:$Q$400,SAC!$J$3:$J$400,$A14) -> R$ 0.00
A15: Outros | B15: =COUNTIFS(SAC!$J$3:$J$400,$A15,SAC!$B$3:$B$400,">="&PAINEL!$B$3,SAC!$B$3:$B$400,"<"&EDATE(PAINEL!$B$3,1)) -> 0 | C15: =COUNTIFS(SAC!$J$3:$J$400,$A15) -> 0 | D15: =SUMIFS(SAC!$Q$3:$Q$400,SAC!$J$3:$J$400,$A15) -> R$ 0.00
A16: TOTAL | B16: =SUM(B6:B15) -> 0 | C16: =SUM(C6:C15) -> 0 | D16: =SUM(D6:D15) -> R$ 0.00
A18: TENDENCIA - ULTIMOS 6 MESES
A19: Mes | B19: Chamados recebidos | C19: Chamados resolvidos | D19: Custo (R$)
A20: =EDATE(PAINEL!$B$3,-5) -> Apr/26 | B20: =COUNTIFS(SAC!$B$3:$B$400,">="&A20,SAC!$B$3:$B$400,"<"&EDATE(A20,1)) -> 0 | C20: =COUNTIFS(SAC!$N$3:$N$400,">="&A20,SAC!$N$3:$N$400,"<"&EDATE(A20,1)) -> 0 | D20: =SUMIFS(SAC!$Q$3:$Q$400,SAC!$B$3:$B$400,">="&A20,SAC!$B$3:$B$400,"<"&EDATE(A20,1)) -> R$ 0.00
A21: =EDATE(PAINEL!$B$3,-4) -> May/26 | B21: =COUNTIFS(SAC!$B$3:$B$400,">="&A21,SAC!$B$3:$B$400,"<"&EDATE(A21,1)) -> 0 | C21: =COUNTIFS(SAC!$N$3:$N$400,">="&A21,SAC!$N$3:$N$400,"<"&EDATE(A21,1)) -> 0 | D21: =SUMIFS(SAC!$Q$3:$Q$400,SAC!$B$3:$B$400,">="&A21,SAC!$B$3:$B$400,"<"&EDATE(A21,1)) -> R$ 0.00
A22: =EDATE(PAINEL!$B$3,-3) -> Jun/26 | B22: =COUNTIFS(SAC!$B$3:$B$400,">="&A22,SAC!$B$3:$B$400,"<"&EDATE(A22,1)) -> 0 | C22: =COUNTIFS(SAC!$N$3:$N$400,">="&A22,SAC!$N$3:$N$400,"<"&EDATE(A22,1)) -> 0 | D22: =SUMIFS(SAC!$Q$3:$Q$400,SAC!$B$3:$B$400,">="&A22,SAC!$B$3:$B$400,"<"&EDATE(A22,1)) -> R$ 0.00
A23: =EDATE(PAINEL!$B$3,-2) -> Jul/26 | B23: =COUNTIFS(SAC!$B$3:$B$400,">="&A23,SAC!$B$3:$B$400,"<"&EDATE(A23,1)) -> 0 | C23: =COUNTIFS(SAC!$N$3:$N$400,">="&A23,SAC!$N$3:$N$400,"<"&EDATE(A23,1)) -> 0 | D23: =SUMIFS(SAC!$Q$3:$Q$400,SAC!$B$3:$B$400,">="&A23,SAC!$B$3:$B$400,"<"&EDATE(A23,1)) -> R$ 0.00
A24: =EDATE(PAINEL!$B$3,-1) -> Aug/26 | B24: =COUNTIFS(SAC!$B$3:$B$400,">="&A24,SAC!$B$3:$B$400,"<"&EDATE(A24,1)) -> 0 | C24: =COUNTIFS(SAC!$N$3:$N$400,">="&A24,SAC!$N$3:$N$400,"<"&EDATE(A24,1)) -> 0 | D24: =SUMIFS(SAC!$Q$3:$Q$400,SAC!$B$3:$B$400,">="&A24,SAC!$B$3:$B$400,"<"&EDATE(A24,1)) -> R$ 0.00
A25: =EDATE(PAINEL!$B$3,-0) -> Sep/26 | B25: =COUNTIFS(SAC!$B$3:$B$400,">="&A25,SAC!$B$3:$B$400,"<"&EDATE(A25,1)) -> 0 | C25: =COUNTIFS(SAC!$N$3:$N$400,">="&A25,SAC!$N$3:$N$400,"<"&EDATE(A25,1)) -> 0 | D25: =SUMIFS(SAC!$Q$3:$Q$400,SAC!$B$3:$B$400,">="&A25,SAC!$B$3:$B$400,"<"&EDATE(A25,1)) -> R$ 0.00
A27: Os graficos atualizam automaticamente ao preencher a coluna 'Causa raiz' na aba SAC com uma das categorias da lista.
A29: CONTROLE DIARIO - AGOSTO/2026 A JANEIRO/2027
A30: Dia | B30: Chamados abertos | C30: Chamados resolvidos | D30: Custo (R$)
A31: 46235 | B31: =COUNTIFS(SAC!$B$3:$B$400,A31) -> 0 | C31: =COUNTIFS(SAC!$N$3:$N$400,A31) -> 0 | D31: =SUMIFS(SAC!$Q$3:$Q$400,SAC!$B$3:$B$400,A31) -> R$ 0.00
A32: =A31+1 -> 02/08/2026 | B32: =COUNTIFS(SAC!$B$3:$B$400,A32) -> 0 | C32: =COUNTIFS(SAC!$N$3:$N$400,A32) -> 0 | D32: =SUMIFS(SAC!$Q$3:$Q$400,SAC!$B$3:$B$400,A32) -> R$ 0.00
A33: =A32+1 -> 03/08/2026 | B33: =COUNTIFS(SAC!$B$3:$B$400,A33) -> 0 | C33: =COUNTIFS(SAC!$N$3:$N$400,A33) -> 0 | D33: =SUMIFS(SAC!$Q$3:$Q$400,SAC!$B$3:$B$400,A33) -> R$ 0.00
A34: =A33+1 -> 04/08/2026 | B34: =COUNTIFS(SAC!$B$3:$B$400,A34) -> 0 | C34: =COUNTIFS(SAC!$N$3:$N$400,A34) -> 0 | D34: =SUMIFS(SAC!$Q$3:$Q$400,SAC!$B$3:$B$400,A34) -> R$ 0.00
A35: =A34+1 -> 05/08/2026 | B35: =COUNTIFS(SAC!$B$3:$B$400,A35) -> 0 | C35: =COUNTIFS(SAC!$N$3:$N$400,A35) -> 0 | D35: =SUMIFS(SAC!$Q$3:$Q$400,SAC!$B$3:$B$400,A35) -> R$ 0.00
A36: =A35+1 -> 06/08/2026 | B36: =COUNTIFS(SAC!$B$3:$B$400,A36) -> 0 | C36: =COUNTIFS(SAC!$N$3:$N$400,A36) -> 0 | D36: =SUMIFS(SAC!$Q$3:$Q$400,SAC!$B$3:$B$400,A36) -> R$ 0.00
A37: =A36+1 -> 07/08/2026 | B37: =COUNTIFS(SAC!$B$3:$B$400,A37) -> 0 | C37: =COUNTIFS(SAC!$N$3:$N$400,A37) -> 0 | D37: =SUMIFS(SAC!$Q$3:$Q$400,SAC!$B$3:$B$400,A37) -> R$ 0.00
A38: =A37+1 -> 08/08/2026 | B38: =COUNTIFS(SAC!$B$3:$B$400,A38) -> 0 | C38: =COUNTIFS(SAC!$N$3:$N$400,A38) -> 0 | D38: =SUMIFS(SAC!$Q$3:$Q$400,SAC!$B$3:$B$400,A38) -> R$ 0.00
A39: =A38+1 -> 09/08/2026 | B39: =COUNTIFS(SAC!$B$3:$B$400,A39) -> 0 | C39: =COUNTIFS(SAC!$N$3:$N$400,A39) -> 0 | D39: =SUMIFS(SAC!$Q$3:$Q$400,SAC!$B$3:$B$400,A39) -> R$ 0.00
A40: =A39+1 -> 10/08/2026 | B40: =COUNTIFS(SAC!$B$3:$B$400,A40) -> 0 | C40: =COUNTIFS(SAC!$N$3:$N$400,A40) -> 0 | D40: =SUMIFS(SAC!$Q$3:$Q$400,SAC!$B$3:$B$400,A40) -> R$ 0.00
A41: =A40+1 -> 11/08/2026 | B41: =COUNTIFS(SAC!$B$3:$B$400,A41) -> 0 | C41: =COUNTIFS(SAC!$N$3:$N$400,A41) -> 0 | D41: =SUMIFS(SAC!$Q$3:$Q$400,SAC!$B$3:$B$400,A41) -> R$ 0.00
A42: =A41+1 -> 12/08/2026 | B42: =COUNTIFS(SAC!$B$3:$B$400,A42) -> 0 | C42: =COUNTIFS(SAC!$N$3:$N$400,A42) -> 0 | D42: =SUMIFS(SAC!$Q$3:$Q$400,SAC!$B$3:$B$400,A42) -> R$ 0.00
A43: =A42+1 -> 13/08/2026 | B43: =COUNTIFS(SAC!$B$3:$B$400,A43) -> 0 | C43: =COUNTIFS(SAC!$N$3:$N$400,A43) -> 0 | D43: =SUMIFS(SAC!$Q$3:$Q$400,SAC!$B$3:$B$400,A43) -> R$ 0.00
... A214: =A213+1 -> 31/01/2027 | B214: =COUNTIFS(SAC!$B$3:$B$400,A214) -> 0 | C214: =COUNTIFS(SAC!$N$3:$N$400,A214) -> 0 | D214: =SUMIFS(SAC!$Q$3:$Q$400,SAC!$B$3:$B$400,A214) -> R$ 0.00
...

Sheet RESUMO MENSAL
A1: RESUMO MENSAL DO SAC - AGOSTO/2026 A JANEIRO/2027
A3: Indicador | B3: 46235 | C3: 46266 | D3: 46296 | E3: 46327 | F3: 46357 | G3: 46388
A4: Chamados recebidos | B4: =COUNTIFS(SAC!$B$3:$B$400,">="&B$3,SAC!$B$3:$B$400,"<"&EDATE(B$3,1)) -> 0 | C4: =COUNTIFS(SAC!$B$3:$B$400,">="&C$3,SAC!$B$3:$B$400,"<"&EDATE(C$3,1)) -> 0 | D4: =COUNTIFS(SAC!$B$3:$B$400,">="&D$3,SAC!$B$3:$B$400,"<"&EDATE(D$3,1)) -> 0 | E4: =COUNTIFS(SAC!$B$3:$B$400,">="&E$3,SAC!$B$3:$B$400,"<"&EDATE(E$3,1)) -> 0 | F4: =COUNTIFS(SAC!$B$3:$B$400,">="&F$3,SAC!$B$3:$B$400,"<"&EDATE(F$3,1)) -> 0 | G4: =COUNTIFS(SAC!$B$3:$B$400,">="&G$3,SAC!$B$3:$B$400,"<"&EDATE(G$3,1)) -> 0
A5: Chamados resolvidos | B5: =COUNTIFS(SAC!$N$3:$N$400,">="&B$3,SAC!$N$3:$N$400,"<"&EDATE(B$3,1)) -> 0 | C5: =COUNTIFS(SAC!$N$3:$N$400,">="&C$3,SAC!$N$3:$N$400,"<"&EDATE(C$3,1)) -> 0 | D5: =COUNTIFS(SAC!$N$3:$N$400,">="&D$3,SAC!$N$3:$N$400,"<"&EDATE(D$3,1)) -> 0 | E5: =COUNTIFS(SAC!$N$3:$N$400,">="&E$3,SAC!$N$3:$N$400,"<"&EDATE(E$3,1)) -> 0 | F5: =COUNTIFS(SAC!$N$3:$N$400,">="&F$3,SAC!$N$3:$N$400,"<"&EDATE(F$3,1)) -> 0 | G5: =COUNTIFS(SAC!$N$3:$N$400,">="&G$3,SAC!$N$3:$N$400,"<"&EDATE(G$3,1)) -> 0
A6: Pendentes (abertos no mes sem resolucao) | B6: =COUNTIFS(SAC!$B$3:$B$400,">="&B$3,SAC!$B$3:$B$400,"<"&EDATE(B$3,1),SAC!$N$3:$N$400,"") -> 0 | C6: =COUNTIFS(SAC!$B$3:$B$400,">="&C$3,SAC!$B$3:$B$400,"<"&EDATE(C$3,1),SAC!$N$3:$N$400,"") -> 0 | D6: =COUNTIFS(SAC!$B$3:$B$400,">="&D$3,SAC!$B$3:$B$400,"<"&EDATE(D$3,1),SAC!$N$3:$N$400,"") -> 0 | E6: =COUNTIFS(SAC!$B$3:$B$400,">="&E$3,SAC!$B$3:$B$400,"<"&EDATE(E$3,1),SAC!$N$3:$N$400,"") -> 0 | F6: =COUNTIFS(SAC!$B$3:$B$400,">="&F$3,SAC!$B$3:$B$400,"<"&EDATE(F$3,1),SAC!$N$3:$N$400,"") -> 0 | G6: =COUNTIFS(SAC!$B$3:$B$400,">="&G$3,SAC!$B$3:$B$400,"<"&EDATE(G$3,1),SAC!$N$3:$N$400,"") -> 0
A7: Tempo medio de resposta (dias) | B7: =IFERROR(AVERAGEIFS(SAC!$O$3:$O$400,SAC!$B$3:$B$400,">="&B$3,SAC!$B$3:$B$400,"<"&EDATE(B$3,1)),0) -> 0.0 | C7: =IFERROR(AVERAGEIFS(SAC!$O$3:$O$400,SAC!$B$3:$B$400,">="&C$3,SAC!$B$3:$B$400,"<"&EDATE(C$3,1)),0) -> 0.0 | D7: =IFERROR(AVERAGEIFS(SAC!$O$3:$O$400,SAC!$B$3:$B$400,">="&D$3,SAC!$B$3:$B$400,"<"&EDATE(D$3,1)),0) -> 0.0 | E7: =IFERROR(AVERAGEIFS(SAC!$O$3:$O$400,SAC!$B$3:$B$400,">="&E$3,SAC!$B$3:$B$400,"<"&EDATE(E$3,1)),0) -> 0.0 | F7: =IFERROR(AVERAGEIFS(SAC!$O$3:$O$400,SAC!$B$3:$B$400,">="&F$3,SAC!$B$3:$B$400,"<"&EDATE(F$3,1)),0) -> 0.0 | G7: =IFERROR(AVERAGEIFS(SAC!$O$3:$O$400,SAC!$B$3:$B$400,">="&G$3,SAC!$B$3:$B$400,"<"&EDATE(G$3,1)),0) -> 0.0
A8: Tempo medio de solucao (dias) | B8: =IFERROR(AVERAGEIFS(SAC!$P$3:$P$400,SAC!$B$3:$B$400,">="&B$3,SAC!$B$3:$B$400,"<"&EDATE(B$3,1)),0) -> 0.0 | C8: =IFERROR(AVERAGEIFS(SAC!$P$3:$P$400,SAC!$B$3:$B$400,">="&C$3,SAC!$B$3:$B$400,"<"&EDATE(C$3,1)),0) -> 0.0 | D8: =IFERROR(AVERAGEIFS(SAC!$P$3:$P$400,SAC!$B$3:$B$400,">="&D$3,SAC!$B$3:$B$400,"<"&EDATE(D$3,1)),0) -> 0.0 | E8: =IFERROR(AVERAGEIFS(SAC!$P$3:$P$400,SAC!$B$3:$B$400,">="&E$3,SAC!$B$3:$B$400,"<"&EDATE(E$3,1)),0) -> 0.0 | F8: =IFERROR(AVERAGEIFS(SAC!$P$3:$P$400,SAC!$B$3:$B$400,">="&F$3,SAC!$B$3:$B$400,"<"&EDATE(F$3,1)),0) -> 0.0 | G8: =IFERROR(AVERAGEIFS(SAC!$P$3:$P$400,SAC!$B$3:$B$400,">="&G$3,SAC!$B$3:$B$400,"<"&EDATE(G$3,1)),0) -> 0.0
A9: Reclamacoes | B9: =COUNTIFS(SAC!$H$3:$H$400,"Reclamacao",SAC!$B$3:$B$400,">="&B$3,SAC!$B$3:$B$400,"<"&EDATE(B$3,1)) -> 0 | C9: =COUNTIFS(SAC!$H$3:$H$400,"Reclamacao",SAC!$B$3:$B$400,">="&C$3,SAC!$B$3:$B$400,"<"&EDATE(C$3,1)) -> 0 | D9: =COUNTIFS(SAC!$H$3:$H$400,"Reclamacao",SAC!$B$3:$B$400,">="&D$3,SAC!$B$3:$B$400,"<"&EDATE(D$3,1)) -> 0 | E9: =COUNTIFS(SAC!$H$3:$H$400,"Reclamacao",SAC!$B$3:$B$400,">="&E$3,SAC!$B$3:$B$400,"<"&EDATE(E$3,1)) -> 0 | F9: =COUNTIFS(SAC!$H$3:$H$400,"Reclamacao",SAC!$B$3:$B$400,">="&F$3,SAC!$B$3:$B$400,"<"&EDATE(F$3,1)) -> 0 | G9: =COUNTIFS(SAC!$H$3:$H$400,"Reclamacao",SAC!$B$3:$B$400,">="&G$3,SAC!$B$3:$B$400,"<"&EDATE(G$3,1)) -> 0
A10: Trocas | B10: =COUNTIFS(SAC!$H$3:$H$400,"Troca",SAC!$B$3:$B$400,">="&B$3,SAC!$B$3:$B$400,"<"&EDATE(B$3,1)) -> 0 | C10: =COUNTIFS(SAC!$H$3:$H$400,"Troca",SAC!$B$3:$B$400,">="&C$3,SAC!$B$3:$B$400,"<"&EDATE(C$3,1)) -> 0 | D10: =COUNTIFS(SAC!$H$3:$H$400,"Troca",SAC!$B$3:$B$400,">="&D$3,SAC!$B$3:$B$400,"<"&EDATE(D$3,1)) -> 0 | E10: =COUNTIFS(SAC!$H$3:$H$400,"Troca",SAC!$B$3:$B$400,">="&E$3,SAC!$B$3:$B$400,"<"&EDATE(E$3,1)) -> 0 | F10: =COUNTIFS(SAC!$H$3:$H$400,"Troca",SAC!$B$3:$B$400,">="&F$3,SAC!$B$3:$B$400,"<"&EDATE(F$3,1)) -> 0 | G10: =COUNTIFS(SAC!$H$3:$H$400,"Troca",SAC!$B$3:$B$400,">="&G$3,SAC!$B$3:$B$400,"<"&EDATE(G$3,1)) -> 0
A11: Avarias | B11: =COUNTIFS(SAC!$H$3:$H$400,"Avaria",SAC!$B$3:$B$400,">="&B$3,SAC!$B$3:$B$400,"<"&EDATE(B$3,1)) -> 0 | C11: =COUNTIFS(SAC!$H$3:$H$400,"Avaria",SAC!$B$3:$B$400,">="&C$3,SAC!$B$3:$B$400,"<"&EDATE(C$3,1)) -> 0 | D11: =COUNTIFS(SAC!$H$3:$H$400,"Avaria",SAC!$B$3:$B$400,">="&D$3,SAC!$B$3:$B$400,"<"&EDATE(D$3,1)) -> 0 | E11: =COUNTIFS(SAC!$H$3:$H$400,"Avaria",SAC!$B$3:$B$400,">="&E$3,SAC!$B$3:$B$400,"<"&EDATE(E$3,1)) -> 0 | F11: =COUNTIFS(SAC!$H$3:$H$400,"Avaria",SAC!$B$3:$B$400,">="&F$3,SAC!$B$3:$B$400,"<"&EDATE(F$3,1)) -> 0 | G11: =COUNTIFS(SAC!$H$3:$H$400,"Avaria",SAC!$B$3:$B$400,">="&G$3,SAC!$B$3:$B$400,"<"&EDATE(G$3,1)) -> 0
A12: Pecas faltantes | B12: =COUNTIFS(SAC!$H$3:$H$400,"Peca faltante",SAC!$B$3:$B$400,">="&B$3,SAC!$B$3:$B$400,"<"&EDATE(B$3,1)) -> 0 | C12: =COUNTIFS(SAC!$H$3:$H$400,"Peca faltante",SAC!$B$3:$B$400,">="&C$3,SAC!$B$3:$B$400,"<"&EDATE(C$3,1)) -> 0 | D12: =COUNTIFS(SAC!$H$3:$H$400,"Peca faltante",SAC!$B$3:$B$400,">="&D$3,SAC!$B$3:$B$400,"<"&EDATE(D$3,1)) -> 0 | E12: =COUNTIFS(SAC!$H$3:$H$400,"Peca faltante",SAC!$B$3:$B$400,">="&E$3,SAC!$B$3:$B$400,"<"&EDATE(E$3,1)) -> 0 | F12: =COUNTIFS(SAC!$H$3:$H$400,"Peca faltante",SAC!$B$3:$B$400,">="&F$3,SAC!$B$3:$B$400,"<"&EDATE(F$3,1)) -> 0 | G12: =COUNTIFS(SAC!$H$3:$H$400,"Peca faltante",SAC!$B$3:$B$400,">="&G$3,SAC!$B$3:$B$400,"<"&EDATE(G$3,1)) -> 0
A13: Satisfacao media (1-5) | B13: =IFERROR(AVERAGEIFS(SAC!$R$3:$R$400,SAC!$B$3:$B$400,">="&B$3,SAC!$B$3:$B$400,"<"&EDATE(B$3,1)),0) -> 0.0 | C13: =IFERROR(AVERAGEIFS(SAC!$R$3:$R$400,SAC!$B$3:$B$400,">="&C$3,SAC!$B$3:$B$400,"<"&EDATE(C$3,1)),0) -> 0.0 | D13: =IFERROR(AVERAGEIFS(SAC!$R$3:$R$400,SAC!$B$3:$B$400,">="&D$3,SAC!$B$3:$B$400,"<"&EDATE(D$3,1)),0) -> 0.0 | E13: =IFERROR(AVERAGEIFS(SAC!$R$3:$R$400,SAC!$B$3:$B$400,">="&E$3,SAC!$B$3:$B$400,"<"&EDATE(E$3,1)),0) -> 0.0 | F13: =IFERROR(AVERAGEIFS(SAC!$R$3:$R$400,SAC!$B$3:$B$400,">="&F$3,SAC!$B$3:$B$400,"<"&EDATE(F$3,1)),0) -> 0.0 | G13: =IFERROR(AVERAGEIFS(SAC!$R$3:$R$400,SAC!$B$3:$B$400,">="&G$3,SAC!$B$3:$B$400,"<"&EDATE(G$3,1)),0) -> 0.0
A14: Pos-vendas realizados | B14: =COUNTIFS('POS-VENDA'!$A$3:$A$150,">="&B$3,'POS-VENDA'!$A$3:$A$150,"<"&EDATE(B$3,1)) -> 0 | C14: =COUNTIFS('POS-VENDA'!$A$3:$A$150,">="&C$3,'POS-VENDA'!$A$3:$A$150,"<"&EDATE(C$3,1)) -> 0 | D14: =COUNTIFS('POS-VENDA'!$A$3:$A$150,">="&D$3,'POS-VENDA'!$A$3:$A$150,"<"&EDATE(D$3,1)) -> 0 | E14: =COUNTIFS('POS-VENDA'!$A$3:$A$150,">="&E$3,'POS-VENDA'!$A$3:$A$150,"<"&EDATE(E$3,1)) -> 0 | F14: =COUNTIFS('POS-VENDA'!$A$3:$A$150,">="&F$3,'POS-VENDA'!$A$3:$A$150,"<"&EDATE(F$3,1)) -> 0 | G14: =COUNTIFS('POS-VENDA'!$A$3:$A$150,">="&G$3,'POS-VENDA'!$A$3:$A$150,"<"&EDATE(G$3,1)) -> 0
A15: Recompras no mes | B15: =COUNTIFS('CLIENTES E RECOMPRA'!$G$3:$G$150,"Sim",'CLIENTES E RECOMPRA'!$H$3:$H$150,">="&B$3,'CLIENTES E RECOMPRA'!$H$3:$H$150,"<"&EDATE(B$3,1)) -> 0 | C15: =COUNTIFS('CLIENTES E RECOMPRA'!$G$3:$G$150,"Sim",'CLIENTES E RECOMPRA'!$H$3:$H$150,">="&C$3,'CLIENTES E RECOMPRA'!$H$3:$H$150,"<"&EDATE(C$3,1)) -> 0 | D15: =COUNTIFS('CLIENTES E RECOMPRA'!$G$3:$G$150,"Sim",'CLIENTES E RECOMPRA'!$H$3:$H$150,">="&D$3,'CLIENTES E RECOMPRA'!$H$3:$H$150,"<"&EDATE(D$3,1)) -> 0 | E15: =COUNTIFS('CLIENTES E RECOMPRA'!$G$3:$G$150,"Sim",'CLIENTES E RECOMPRA'!$H$3:$H$150,">="&E$3,'CLIENTES E RECOMPRA'!$H$3:$H$150,"<"&EDATE(E$3,1)) -> 0 | F15: =COUNTIFS('CLIENTES E RECOMPRA'!$G$3:$G$150,"Sim",'CLIENTES E RECOMPRA'!$H$3:$H$150,">="&F$3,'CLIENTES E RECOMPRA'!$H$3:$H$150,"<"&EDATE(F$3,1)) -> 0 | G15: =COUNTIFS('CLIENTES E RECOMPRA'!$G$3:$G$150,"Sim",'CLIENTES E RECOMPRA'!$H$3:$H$150,">="&G$3,'CLIENTES E RECOMPRA'!$H$3:$H$150,"<"&EDATE(G$3,1)) -> 0
A16: Custo gerado pelo SAC (R$) | B16: =SUMIFS(SAC!$Q$3:$Q$400,SAC!$B$3:$B$400,">="&B$3,SAC!$B$3:$B$400,"<"&EDATE(B$3,1)) -> R$ 0.00 | C16: =SUMIFS(SAC!$Q$3:$Q$400,SAC!$B$3:$B$400,">="&C$3,SAC!$B$3:$B$400,"<"&EDATE(C$3,1)) -> R$ 0.00 | D16: =SUMIFS(SAC!$Q$3:$Q$400,SAC!$B$3:$B$400,">="&D$3,SAC!$B$3:$B$400,"<"&EDATE(D$3,1)) -> R$ 0.00 | E16: =SUMIFS(SAC!$Q$3:$Q$400,SAC!$B$3:$B$400,">="&E$3,SAC!$B$3:$B$400,"<"&EDATE(E$3,1)) -> R$ 0.00 | F16: =SUMIFS(SAC!$Q$3:$Q$400,SAC!$B$3:$B$400,">="&F$3,SAC!$B$3:$B$400,"<"&EDATE(F$3,1)) -> R$ 0.00 | G16: =SUMIFS(SAC!$Q$3:$Q$400,SAC!$B$3:$B$400,">="&G$3,SAC!$B$3:$B$400,"<"&EDATE(G$3,1)) -> R$ 0.00
A18: Mapa de cores: verde = melhor valor da linha, vermelho = pior valor da linha (comparativo entre os 6 meses).
A20: GRAFICOS MES A MES

Sheet BASE NC
A1: BASE UNICA DE RECLAMACOES | O1: INDICADORES
O2: Total de reclamacoes | P2: =COUNTIF($A$5:$A$302,"<>") -> 0
A3: Data | B3: Pedido | C3: Produto | D3: Reclamacao | E3: Categoria | F3: Falha da embalagem | G3: Causa provavel | H3: Setor responsavel | I3: Solucao | J3: Custo (R$) | K3: Transportadora | L3: Reincidencia | M3: Status | O3: Custo total (R$) | P3: =SUMIF($A$5:$A$302,"<>",$J$5:$J$302) -> R$ 0.00
A4: 46270 | B4: PED-10234 | C4: Lavatorio/Shampoo | D4: Cliente relatou vazamento na cuba apos poucos dias de uso | E4: Hidraulica | G4: Producao interna | H4: Producao | I4: Peca substituida em garantia | J4: 150 | K4: Transportadora Rapida | L4: Nao | M4: Resolvido | O4: % reincidencia | P4: =IFERROR(COUNTIF($L$5:$L$302,"Sim")/COUNTIF($A$5:$A$302,"<>"),0) -> 0.0%
O5: Custo medio por reclamacao (R$) | P5: =IFERROR(SUMIF($A$5:$A$302,"<>",$J$5:$J$302)/COUNTIF($A$5:$A$302,"<>"),0) -> R$ 0.00
A304: RESUMO - CATEGORIA DA RECLAMACAO
A305: Categoria | B305: Qtd | C305: Custo (R$)
A306: Acabamento | B306: =COUNTIF($E$5:$E$302,$A306) -> 0 | C306: =SUMIF($E$5:$E$302,$A306,$J$5:$J$302) -> R$ 0.00 | G306: =B306*1000-1 -> -1
A307: Embalagem | B307: =COUNTIF($E$5:$E$302,$A307) -> 0 | C307: =SUMIF($E$5:$E$302,$A307,$J$5:$J$302) -> R$ 0.00 | G307: =B307*1000-2 -> -2
A308: Material | B308: =COUNTIF($E$5:$E$302,$A308) -> 0 | C308: =SUMIF($E$5:$E$302,$A308,$J$5:$J$302) -> R$ 0.00 | G308: =B308*1000-3 -> -3
A309: Hidraulica | B309: =COUNTIF($E$5:$E$302,$A309) -> 0 | C309: =SUMIF($E$5:$E$302,$A309,$J$5:$J$302) -> R$ 0.00 | G309: =B309*1000-4 -> -4
A310: Costura | B310: =COUNTIF($E$5:$E$302,$A310) -> 0 | C310: =SUMIF($E$5:$E$302,$A310,$J$5:$J$302) -> R$ 0.00 | G310: =B310*1000-5 -> -5
A311: Montagem | B311: =COUNTIF($E$5:$E$302,$A311) -> 0 | C311: =SUMIF($E$5:$E$302,$A311,$J$5:$J$302) -> R$ 0.00 | G311: =B311*1000-6 -> -6
A312: Peca faltante | B312: =COUNTIF($E$5:$E$302,$A312) -> 0 | C312: =SUMIF($E$5:$E$302,$A312,$J$5:$J$302) -> R$ 0.00 | G312: =B312*1000-7 -> -7
A313: Peca quebrada | B313: =COUNTIF($E$5:$E$302,$A313) -> 0 | C313: =SUMIF($E$5:$E$302,$A313,$J$5:$J$302) -> R$ 0.00 | G313: =B313*1000-8 -> -8
A314: Dificuldade de montagem | B314: =COUNTIF($E$5:$E$302,$A314) -> 0 | C314: =SUMIF($E$5:$E$302,$A314,$J$5:$J$302) -> R$ 0.00 | G314: =B314*1000-9 -> -9
A315: Outros | B315: =COUNTIF($E$5:$E$302,$A315) -> 0 | C315: =SUMIF($E$5:$E$302,$A315,$J$5:$J$302) -> R$ 0.00 | G315: =B315*1000-10 -> -10
A317: RESUMO - FALHA DA EMBALAGEM
A318: Falha | B318: Qtd
A319: Sem protecao/calco interno | B319: =COUNTIF($F$5:$F$302,$A319) -> 0 | G319: =B319*1000-1 -> -1
A320: Caixa amassada ou papelao fino | B320: =COUNTIF($F$5:$F$302,$A320) -> 0 | G320: =B320*1000-2 -> -2
A321: Falta fita de reforco | B321: =COUNTIF($F$5:$F$302,$A321) -> 0 | G321: =B321*1000-3 -> -3
A322: Sem plastico bolha/espuma | B322: =COUNTIF($F$5:$F$302,$A322) -> 0 | G322: =B322*1000-4 -> -4
A323: Caixa subdimensionada para o produto | B323: =COUNTIF($F$5:$F$302,$A323) -> 0 | G323: =B323*1000-5 -> -5
A324: Etiqueta de fragil ausente | B324: =COUNTIF($F$5:$F$302,$A324) -> 0 | G324: =B324*1000-6 -> -6
A325: Fixacao/paletizacao inadequada | B325: =COUNTIF($F$5:$F$302,$A325) -> 0 | G325: =B325*1000-7 -> -7
A326: Outros | B326: =COUNTIF($F$5:$F$302,$A326) -> 0 | G326: =B326*1000-8 -> -8
A328: RESUMO - SETOR RESPONSAVEL
A329: Setor | B329: Qtd
A330: Producao | B330: =COUNTIF($H$5:$H$302,$A330) -> 0
A331: Qualidade | B331: =COUNTIF($H$5:$H$302,$A331) -> 0
A332: Logistica/Expedicao | B332: =COUNTIF($H$5:$H$302,$A332) -> 0
A333: Compras/Fornecedor | B333: =COUNTIF($H$5:$H$302,$A333) -> 0
A334: Comercial/Atendimento | B334: =COUNTIF($H$5:$H$302,$A334) -> 0
A335: Design/Engenharia | B335: =COUNTIF($H$5:$H$302,$A335) -> 0
A336: Outro | B336: =COUNTIF($H$5:$H$302,$A336) -> 0
A338: RESUMO - PRODUTO
A339: Produto | B339: Qtd
A340: Cadeira de cabelo | B340: =COUNTIF($C$5:$C$302,$A340) -> 0
A341: Lavatorio/Shampoo | B341: =COUNTIF($C$5:$C$302,$A341) -> 0
...

Sheet SAC
A1: ID | B1: Data abertura | C1: Cliente | D1: Contato | E1: Canal | F1: Categoria produto | G1: Produto/Pedido | H1: Tipo de chamado | I1: Descricao do problema | J1: Causa raiz | K1: Prioridade | L1: Status | M1: Responsavel | N1: Data resolucao | O1: Tempo resposta (dias) | P1: Tempo solucao (dias) | Q1: Custo gerado (R$) | R1: Satisfacao (1-5) | S1: Observacoes | U1: RESUMO - STATUS ATUAL | X1: RESUMO - CATEGORIA DO DEFEITO
A2: 1 | B2: 46266 | C2: Salao Bela Vida | D2: (11) 90000-0000 | E2: WhatsApp | F2: Cadeira de cabelo | G2: Pedido 4521 | H2: Avaria | I2: Cadeira chegou com o pistao hidraulico com vazamento | J2: Hidraulica | K2: Alta | L2: Em andamento | M2: Ana | O2: =IF(N2="","",N2-B2) | P2: =IF(O2="","",O2-B2) | Q2: 0 | S2: Aguardando peca do fornecedor | U2: Status | V2: Qtd | X2: Categoria | Y2: Qtd
A3: =IF(B3="","",1) | O3: =IF(OR(B3="",N3=""),"",N3-B3) | P3: =IF(OR(B3="",N3=""),"",N3-B3) | U3: Aberto | V3: =COUNTIF(L3:L400,U3) -> 0 | X3: Acabamento | Y3: =COUNTIF(J3:J400,X3) -> 0 | AD3: =Y3*1000-1 -> -1
A4: =IF(B4="","",A3+1) | O4: =IF(OR(B4="",N4=""),"",N4-B4) | P4: =IF(OR(B4="",N4=""),"",N4-B4) | U4: Em andamento | V4: =COUNTIF(L3:L400,U4) -> 0 | X4: Embalagem | Y4: =COUNTIF(J3:J400,X4) -> 0 | AD4: =Y4*1000-2 -> -2
A5: =IF(B5="","",A4+1) | O5: =IF(OR(B5="",N5=""),"",N5-B5) | P5: =IF(OR(B5="",N5=""),"",N5-B5) | U5: Aguardando cliente | V5: =COUNTIF(L3:L400,U5) -> 0 | X5: Material | Y5: =COUNTIF(J3:J400,X5) -> 0 | AD5: =Y5*1000-3 -> -3
A6: =IF(B6="","",A5+1) | O6: =IF(OR(B6="",N6=""),"",N6-B6) | P6: =IF(OR(B6="",N6=""),"",N6-B6) | U6: Resolvido | V6: =COUNTIF(L3:L400,U6) -> 0 | X6: Hidraulica | Y6: =COUNTIF(J3:J400,X6) -> 0 | AD6: =Y6*1000-4 -> -4
A7: =IF(B7="","",A6+1) | O7: =IF(OR(B7="",N7=""),"",N7-B7) | P7: =IF(OR(B7="",N7=""),"",N7-B7) | U7: Cancelado | V7: =COUNTIF(L3:L400,U7) -> 0 | X7: Costura | Y7: =COUNTIF(J3:J400,X7) -> 0 | AD7: =Y7*1000-5 -> -5
A8: =IF(B8="","",A7+1) | O8: =IF(OR(B8="",N8=""),"",N8-B8) | P8: =IF(OR(B8="",N8=""),"",N8-B8) | X8: Montagem | Y8: =COUNTIF(J3:J400,X8) -> 0 | AD8: =Y8*1000-6 -> -6
A9: =IF(B9="","",A8+1) | O9: =IF(OR(B9="",N9=""),"",N9-B9) | P9: =IF(OR(B9="",N9=""),"",N9-B9) | X9: Peca faltante | Y9: =COUNTIF(J3:J400,X9) -> 0 | AD9: =Y9*1000-7 -> -7
A10: =IF(B10="","",A9+1) | O10: =IF(OR(B10="",N10=""),"",N10-B10) | P10: =IF(OR(B10="",N10=""),"",N10-B10) | X10: Peca quebrada | Y10: =COUNTIF(J3:J400,X10) -> 0 | AD10: =Y10*1000-8 -> -8
A11: =IF(B11="","",A10+1) | O11: =IF(OR(B11="",N11=""),"",N11-B11) | P11: =IF(OR(B11="",N11=""),"",N11-B11) | X11: Dificuldade de montagem | Y11: =COUNTIF(J3:J400,X11) -> 0 | AD11: =Y11*1000-9 -> -9
A12: =IF(B12="","",A11+1) | O12: =IF(OR(B12="",N12=""),"",N12-B12) | P12: =IF(OR(B12="",N12=""),"",N12-B12) | X12: Outros | Y12: =COUNTIF(J3:J400,X12) -> 0 | AD12: =Y12*1000-10 -> -10
A13: =IF(B13="","",A12+1) | O13: =IF(OR(B13="",N13=""),"",N13-B13) | P13: =IF(OR(B13="",N13=""),"",N13-B13)
A14: =IF(B14="","",A13+1) | O14: =IF(OR(B14="",N14=""),"",N14-B14) | P14: =IF(OR(B14="",N14=""),"",N14-B14)
A15: =IF(B15="","",A14+1) | O15: =IF(OR(B15="",N15=""),"",N15-B15) | P15: =IF(OR(B15="",N15=""),"",N15-B15) | X15: PARETO - Categoria do defeito - SAC
A16: =IF(B16="","",A15+1) | O16: =IF(OR(B16="",N16=""),"",N16-B16) | P16: =IF(OR(B16="",N16=""),"",N16-B16) | X16: Categoria (ordenada) | Y16: Qtd | Z16: % acumulado
A17: =IF(B17="","",A16+1) | O17: =IF(OR(B17="",N17=""),"",N17-B17) | P17: =IF(OR(B17="",N17=""),"",N17-B17) | X17: {=INDEX($X$3:$X$12,MATCH(LARGE($AD$3:$AD$12,1),$AD$3:$AD$12,0))} -> Acabamento | Y17: =ROUND(LARGE($AD$3:$AD$12,1)/1000,0) -> 0 | Z17: =IFERROR(SUM($Y$17:Y17)/SUM($Y$3:$Y$12)*100,0) -> 0.0
A18: =IF(B18="","",A17+1) | O18: =IF(OR(B18="",N18=""),"",N18-B18) | P18: =IF(OR(B18="",N18=""),"",N18-B18) | X18: {=INDEX($X$3:$X$12,MATCH(LARGE($AD$3:$AD$12,2),$AD$3:$AD$12,0))} -> Embalagem | Y18: =ROUND(LARGE($AD$3:$AD$12,2)/1000,0) -> 0 | Z18: =IFERROR(SUM($Y$17:Y18)/SUM($Y$3:$Y$12)*100,0) -> 0.0
A19: =IF(B19="","",A18+1) | O19: =IF(OR(B19="",N19=""),"",N19-B19) | P19: =IF(OR(B19="",N19=""),"",N19-B19) | X19: {=INDEX($X$3:$X$12,MATCH(LARGE($AD$3:$AD$12,3),$AD$3:$AD$12,0))} -> Material | Y19: =ROUND(LARGE($AD$3:$AD$12,3)/1000,0) -> 0 | Z19: =IFERROR(SUM($Y$17:Y19)/SUM($Y$3:$Y$12)*100,0) -> 0.0
A20: =IF(B20="","",A19+1) | O20: =IF(OR(B20="",N20=""),"",N20-B20) | P20: =IF(OR(B20="",N20=""),"",N20-B20) | X20: {=INDEX($X$3:$X$12,MATCH(LARGE($AD$3:$AD$12,4),$AD$3:$AD$12,0))} -> Hidraulica | Y20: =ROUND(LARGE($AD$3:$AD$12,4)/1000,0) -> 0 | Z20: =IFERROR(SUM($Y$17:Y20)/SUM($Y$3:$Y$12)*100,0) -> 0.0
A21: =IF(B21="","",A20+1) | O21: =IF(OR(B21="",N21=""),"",N21-B21) | P21: =IF(OR(B21="",N21=""),"",N21-B21) | X21: {=INDEX($X$3:$X$12,MATCH(LARGE($AD$3:$AD$12,5),$AD$3:$AD$12,0))} -> Costura | Y21: =ROUND(LARGE($AD$3:$AD$12,5)/1000,0) -> 0 | Z21: =IFERROR(SUM($Y$17:Y21)/SUM($Y$3:$Y$12)*100,0) -> 0.0
A22: =IF(B22="","",A21+1) | O22: =IF(OR(B22="",N22=""),"",N22-B22) | P22: =IF(OR(B22="",N22=""),"",N22-B22) | X22: {=INDEX($X$3:$X$12,MATCH(LARGE($AD$3:$AD$12,6),$AD$3:$AD$12,0))} -> Montagem | Y22: =ROUND(LARGE($AD$3:$AD$12,6)/1000,0) -> 0 | Z22: =IFERROR(SUM($Y$17:Y22)/SUM($Y$3:$Y$12)*100,0) -> 0.0
A23: =IF(B23="","",A22+1) | O23: =IF(OR(B23="",N23=""),"",N23-B23) | P23: =IF(OR(B23="",N23=""),"",N23-B23) | X23: {=INDEX($X$3:$X$12,MATCH(LARGE($AD$3:$AD$12,7),$AD$3:$AD$12,0))} -> Peca faltante | Y23: =ROUND(LARGE($AD$3:$AD$12,7)/1000,0) -> 0 | Z23: =IFERROR(SUM($Y$17:Y23)/SUM($Y$3:$Y$12)*100,0) -> 0.0
A24: =IF(B24="","",A23+1) | O24: =IF(OR(B24="",N24=""),"",N24-B24) | P24: =IF(OR(B24="",N24=""),"",N24-B24) | X24: {=INDEX($X$3:$X$12,MATCH(LARGE($AD$3:$AD$12,8),$AD$3:$AD$12,0))} -> Peca quebrada | Y24: =ROUND(LARGE($AD$3:$AD$12,8)/1000,0) -> 0 | Z24: =IFERROR(SUM($Y$17:Y24)/SUM($Y$3:$Y$12)*100,0) -> 0.0
A25: =IF(B25="","",A24+1) | O25: =IF(OR(B25="",N25=""),"",N25-B25) | P25: =IF(OR(B25="",N25=""),"",N25-B25) | X25: {=INDEX($X$3:$X$12,MATCH(LARGE($AD$3:$AD$12,9),$AD$3:$AD$12,0))} -> Dificuldade de montagem | Y25: =ROUND(LARGE($AD$3:$AD$12,9)/1000,0) -> 0 | Z25: =IFERROR(SUM($Y$17:Y25)/SUM($Y$3:$Y$12)*100,0) -> 0.0
A26: =IF(B26="","",A25+1) | O26: =IF(OR(B26="",N26=""),"",N26-B26) | P26: =IF(OR(B26="",N26=""),"",N26-B26) | X26: {=INDEX($X$3:$X$12,MATCH(LARGE($AD$3:$AD$12,10),$AD$3:$AD$12,0))} -> Outros | Y26: =ROUND(LARGE($AD$3:$AD$12,10)/1000,0) -> 0 | Z26: =IFERROR(SUM($Y$17:Y26)/SUM($Y$3:$Y$12)*100,0) -> 0.0
A27: =IF(B27="","",A26+1) | O27: =IF(OR(B27="",N27=""),"",N27-B27) | P27: =IF(OR(B27="",N27=""),"",N27-B27)
A28: =IF(B28="","",A27+1) | O28: =IF(OR(B28="",N28=""),"",N28-B28) | P28: =IF(OR(B28="",N28=""),"",N28-B28)
A29: =IF(B29="","",A28+1) | O29: =IF(OR(B29="",N29=""),"",N29-B29) | P29: =IF(OR(B29="",N29=""),"",N29-B29)
A30: =IF(B30="","",A29+1) | O30: =IF(OR(B30="",N30=""),"",N30-B30) | P30: =IF(OR(B30="",N30=""),"",N30-B30)
A31: =IF(B31="","",A30+1) | O31: =IF(OR(B31="",N31=""),"",N31-B31) | P31: =IF(OR(B31="",N31=""),"",N31-B31)
A32: =IF(B32="","",A31+1) | O32: =IF(OR(B32="",N32=""),"",N32-B32) | P32: =IF(OR(B32="",N32=""),"",N32-B32)
A33: =IF(B33="","",A32+1) | O33: =IF(OR(B33="",N33=""),"",N33-B33) | P33: =IF(OR(B33="",N33=""),"",N33-B33)
A34: =IF(B34="","",A33+1) | O34: =IF(OR(B34="",N34=""),"",N34-B34) | P34: =IF(OR(B34="",N34=""),"",N34-B34)
A35: =IF(B35="","",A34+1) | O35: =IF(OR(B35="",N35=""),"",N35-B35) | P35: =IF(OR(B35="",N35=""),"",N35-B35)
A36: =IF(B36="","",A35+1) | O36: =IF(OR(B36="",N36=""),"",N36-B36) | P36: =IF(OR(B36="",N36=""),"",N36-B36)
A37: =IF(B37="","",A36+1) | O37: =IF(OR(B37="",N37=""),"",N37-B37) | P37: =IF(OR(B37="",N37=""),"",N37-B37)
A38: =IF(B38="","",A37+1) | O38: =IF(OR(B38="",N38=""),"",N38-B38) | P38: =IF(OR(B38="",N38=""),"",N38-B38)
... A400: =IF(B400="","",A399+1) | O400: =IF(OR(B400="",N400=""),"",N400-B400) | P400: =IF(OR(B400="",N400=""),"",N400-B400)

Sheet NC CANAIS
A1: Data da ocorrencia | B1: No da NC | C1: Canal | D1: Produto | E1: Peca danificada | F1: Categoria da reclamacao | G1: Descricao da reclamacao | H1: Tratativa | I1: Resolucao | J1: Prazo | K1: Status | L1: Custo transportadora (R$) | M1: Custo coleta reversa (R$) | N1: Custo reembolso (R$) | O1: Custo da peca (R$) | P1: Custo total (R$) | R1: RESUMO - NC POR CANAL
A2: 46268 | B2: 1 | C2: Mercado Livre | D2: Cadeira de cabelo | E2: Pistao hidraulico | F2: Hidraulica | G2: Cliente relatou vazamento no pistao ao receber o produto | H2: Contato via Mercado Livre, coleta reversa agendada | I2: Peca substituida e enviada nova cadeira ao cliente | J2: 46278 | K2: Resolvido | L2: 80 | M2: 50 | N2: 0 | O2: 120 | P2: =SUM(L2:O2) -> R$ 250.00 | R2: Canal | S2: Qtd | T2: Custo total (R$)
B3: =IF(A3="","",COUNT($A$2:A3)) | P3: =SUM(L3:O3) -> R$ 0.00 | R3: Mercado Livre | S3: =COUNTIFS($C$2:$C300,R3,$A$2:$A300,"<>") -> 1 | T3: =SUMIFS($P$2:$P300,$C$2:$C300,R3) -> R$ 250.00
B4: =IF(A4="","",COUNT($A$2:A4)) | P4: =SUM(L4:O4) -> R$ 0.00 | R4: Instagram | S4: =COUNTIFS($C$2:$C300,R4,$A$2:$A300,"<>") -> 0 | T4: =SUMIFS($P$2:$P300,$C$2:$C300,R4) -> R$ 0.00
B5: =IF(A5="","",COUNT($A$2:A5)) | P5: =SUM(L5:O5) -> R$ 0.00 | R5: Lojista | S5: =COUNTIFS($C$2:$C300,R5,$A$2:$A300,"<>") -> 0 | T5: =SUMIFS($P$2:$P300,$C$2:$C300,R5) -> R$ 0.00
B6: =IF(A6="","",COUNT($A$2:A6)) | P6: =SUM(L6:O6) -> R$ 0.00
B7: =IF(A7="","",COUNT($A$2:A7)) | P7: =SUM(L7:O7) -> R$ 0.00 | R7: RESUMO - NC POR PRODUTO
B8: =IF(A8="","",COUNT($A$2:A8)) | P8: =SUM(L8:O8) -> R$ 0.00 | R8: Produto | S8: Qtd
B9: =IF(A9="","",COUNT($A$2:A9)) | P9: =SUM(L9:O9) -> R$ 0.00 | R9: Cadeira de cabelo | S9: =COUNTIF($D$2:$D300,R9) -> 1
B10: =IF(A10="","",COUNT($A$2:A10)) | P10: =SUM(L10:O10) -> R$ 0.00 | R10: Lavatorio/Shampoo | S10: =COUNTIF($D$2:$D300,R10) -> 0
B11: =IF(A11="","",COUNT($A$2:A11)) | P11: =SUM(L11:O11) -> R$ 0.00 | R11: Carrinho auxiliar | S11: =COUNTIF($D$2:$D300,R11) -> 0
B12: =IF(A12="","",COUNT($A$2:A12)) | P12: =SUM(L12:O12) -> R$ 0.00 | R12: Espelho/Estacao | S12: =COUNTIF($D$2:$D300,R12) -> 0
B13: =IF(A13="","",COUNT($A$2:A13)) | P13: =SUM(L13:O13) -> R$ 0.00 | R13: Recepcao/Sofa | S13: =COUNTIF($D$2:$D300,R13) -> 0
B14: =IF(A14="","",COUNT($A$2:A14)) | P14: =SUM(L14:O14) -> R$ 0.00 | R14: Maca | S14: =COUNTIF($D$2:$D300,R14) -> 0
B15: =IF(A15="","",COUNT($A$2:A15)) | P15: =SUM(L15:O15) -> R$ 0.00 | R15: Outro | S15: =COUNTIF($D$2:$D300,R15) -> 0
B16: =IF(A16="","",COUNT($A$2:A16)) | P16: =SUM(L16:O16) -> R$ 0.00
B17: =IF(A17="","",COUNT($A$2:A17)) | P17: =SUM(L17:O17) -> R$ 0.00 | R17: RESUMO - CATEGORIA DA RECLAMACAO
B18: =IF(A18="","",COUNT($A$2:A18)) | P18: =SUM(L18:O18) -> R$ 0.00 | R18: Categoria | S18: Qtd
B19: =IF(A19="","",COUNT($A$2:A19)) | P19: =SUM(L19:O19) -> R$ 0.00 | R19: Acabamento | S19: =COUNTIF($F$2:$F300,R19) -> 0 | X19: =S19*1000-1 -> -1
B20: =IF(A20="","",COUNT($A$2:A20)) | P20: =SUM(L20:O20) -> R$ 0.00 | R20: Embalagem | S20: =COUNTIF($F$2:$F300,R20) -> 0 | X20: =S20*1000-2 -> -2
B21: =IF(A21="","",COUNT($A$2:A21)) | P21: =SUM(L21:O21) -> R$ 0.00 | R21: Material | S21: =COUNTIF($F$2:$F300,R21) -> 0 | X21: =S21*1000-3 -> -3
B22: =IF(A22="","",COUNT($A$2:A22)) | P22: =SUM(L22:O22) -> R$ 0.00 | R22: Hidraulica | S22: =COUNTIF($F$2:$F300,R22) -> 1 | X22: =S22*1000-4 -> 996
B23: =IF(A23="","",COUNT($A$2:A23)) | P23: =SUM(L23:O23) -> R$ 0.00 | R23: Costura | S23: =COUNTIF($F$2:$F300,R23) -> 0 | X23: =S23*1000-5 -> -5
B24: =IF(A24="","",COUNT($A$2:A24)) | P24: =SUM(L24:O24) -> R$ 0.00 | R24: Montagem | S24: =COUNTIF($F$2:$F300,R24) -> 0 | X24: =S24*1000-6 -> -6
B25: =IF(A25="","",COUNT($A$2:A25)) | P25: =SUM(L25:O25) -> R$ 0.00 | R25: Peca faltante | S25: =COUNTIF($F$2:$F300,R25) -> 0 | X25: =S25*1000-7 -> -7
B26: =IF(A26="","",COUNT($A$2:A26)) | P26: =SUM(L26:O26) -> R$ 0.00 | R26: Peca quebrada | S26: =COUNTIF($F$2:$F300,R26) -> 0 | X26: =S26*1000-8 -> -8
B27: =IF(A27="","",COUNT($A$2:A27)) | P27: =SUM(L27:O27) -> R$ 0.00 | R27: Dificuldade de montagem | S27: =COUNTIF($F$2:$F300,R27) -> 0 | X27: =S27*1000-9 -> -9
B28: =IF(A28="","",COUNT($A$2:A28)) | P28: =SUM(L28:O28) -> R$ 0.00 | R28: Outros | S28: =COUNTIF($F$2:$F300,R28) -> 0 | X28: =S28*1000-10 -> -10
B29: =IF(A29="","",COUNT($A$2:A29)) | P29: =SUM(L29:O29) -> R$ 0.00
B30: =IF(A30="","",COUNT($A$2:A30)) | P30: =SUM(L30:O30) -> R$ 0.00 | R30: RESUMO - STATUS ATUAL
B31: =IF(A31="","",COUNT($A$2:A31)) | P31: =SUM(L31:O31) -> R$ 0.00 | R31: Status | S31: Qtd
B32: =IF(A32="","",COUNT($A$2:A32)) | P32: =SUM(L32:O32) -> R$ 0.00 | R32: Aberto | S32: =COUNTIF($K$2:$K300,R32) -> 0
B33: =IF(A33="","",COUNT($A$2:A33)) | P33: =SUM(L33:O33) -> R$ 0.00 | R33: Em andamento | S33: =COUNTIF($K$2:$K300,R33) -> 0
B34: =IF(A34="","",COUNT($A$2:A34)) | P34: =SUM(L34:O34) -> R$ 0.00 | R34: Aguardando cliente | S34: =COUNTIF($K$2:$K300,R34) -> 0
B35: =IF(A35="","",COUNT($A$2:A35)) | P35: =SUM(L35:O35) -> R$ 0.00 | R35: Resolvido | S35: =COUNTIF($K$2:$K300,R35) -> 1
B36: =IF(A36="","",COUNT($A$2:A36)) | P36: =SUM(L36:O36) -> R$ 0.00 | R36: Cancelado | S36: =COUNTIF($K$2:$K300,R36) -> 0
B37: =IF(A37="","",COUNT($A$2:A37)) | P37: =SUM(L37:O37) -> R$ 0.00
B38: =IF(A38="","",COUNT($A$2:A38)) | P38: =SUM(L38:O38) -> R$ 0.00 | R38: RESUMO - CUSTOS POR TIPO
B39: =IF(A39="","",COUNT($A$2:A39)) | P39: =SUM(L39:O39) -> R$ 0.00 | R39: Tipo de custo | S39: Total (R$)
B40: =IF(A40="","",COUNT($A$2:A40)) | P40: =SUM(L40:O40) -> R$ 0.00 | R40: Transportadora | S40: =SUM($L$2:$L300) -> R$ 80.00
...

Sheet POS-VENDA
A1: Data do contato | B1: Cliente | C1: Produto comprado | D1: Data da compra | E1: Tipo de contato | F1: Satisfacao (1-5) | G1: NPS (0-10) | H1: Comentarios do cliente | I1: Recompra prevista | J1: Responsavel | L1: RESUMO - SATISFACAO
A2: 46266 | B2: Studio Hair Design | C2: Kit 3 cadeiras | D2: 46235 | E2: Follow-up 30 dias | F2: 5 | G2: 9 | H2: Muito satisfeita, elogiou o acabamento | I2: Sim | J2: Ana | L2: Nota | M2: Qtd
L3: 1 | M3: =COUNTIF(F3:F150,L3) -> 0
L4: 2 | M4: =COUNTIF(F3:F150,L4) -> 0
L5: 3 | M5: =COUNTIF(F3:F150,L5) -> 0
L6: 4 | M6: =COUNTIF(F3:F150,L6) -> 0
L7: 5 | M7: =COUNTIF(F3:F150,L7) -> 0

Sheet CAUSAS E QUALIDADE
A1: ID chamado (SAC) | B1: Data | C1: Causa raiz | D1: Setor responsavel | E1: Descricao da nao conformidade | F1: Acao corretiva | G1: Responsavel | H1: Prazo | I1: Status | J1: Reincidencia | L1: RESUMO - CAUSAS
A2: 1 | B2: 46266 | C2: Hidraulica | D2: Logistica/Transportadora | E2: Pistao hidraulico vazando por mau acondicionamento na carga | F2: Revisar procedimento de fixacao da carga com a transportadora | G2: Carlos | H2: 46280 | I2: Em andamento | J2: Nao | L2: Causa | M2: Qtd
L3: Acabamento | M3: =COUNTIF(C3:C150,L3) -> 0 | R3: =M3*1000-1 -> -1
L4: Embalagem | M4: =COUNTIF(C3:C150,L4) -> 0 | R4: =M4*1000-2 -> -2
L5: Material | M5: =COUNTIF(C3:C150,L5) -> 0 | R5: =M5*1000-3 -> -3
L6: Hidraulica | M6: =COUNTIF(C3:C150,L6) -> 0 | R6: =M6*1000-4 -> -4
L7: Costura | M7: =COUNTIF(C3:C150,L7) -> 0 | R7: =M7*1000-5 -> -5
L8: Montagem | M8: =COUNTIF(C3:C150,L8) -> 0 | R8: =M8*1000-6 -> -6
L9: Peca faltante | M9: =COUNTIF(C3:C150,L9) -> 0 | R9: =M9*1000-7 -> -7
L10: Peca quebrada | M10: =COUNTIF(C3:C150,L10) -> 0 | R10: =M10*1000-8 -> -8
L11: Dificuldade de montagem | M11: =COUNTIF(C3:C150,L11) -> 0 | R11: =M11*1000-9 -> -9
L12: Outros | M12: =COUNTIF(C3:C150,L12) -> 0 | R12: =M12*1000-10 -> -10
L36: PARETO - Nao conformidades por causa
L37: Categoria (ordenada) | M37: Qtd | N37: % acumulado
L38: {=INDEX($L$3:$L$12,MATCH(LARGE($R$3:$R$12,1),$R$3:$R$12,0))} -> Acabamento | M38: =ROUND(LARGE($R$3:$R$12,1)/1000,0) -> 0 | N38: =IFERROR(SUM($M$38:M38)/SUM($M$3:$M$12)*100,0) -> 0.0
L39: {=INDEX($L$3:$L$12,MATCH(LARGE($R$3:$R$12,2),$R$3:$R$12,0))} -> Embalagem | M39: =ROUND(LARGE($R$3:$R$12,2)/1000,0) -> 0 | N39: =IFERROR(SUM($M$38:M39)/SUM($M$3:$M$12)*100,0) -> 0.0
L40: {=INDEX($L$3:$L$12,MATCH(LARGE($R$3:$R$12,3),$R$3:$R$12,0))} -> Material | M40: =ROUND(LARGE($R$3:$R$12,3)/1000,0) -> 0 | N40: =IFERROR(SUM($M$38:M40)/SUM($M$3:$M$12)*100,0) -> 0.0
L41: {=INDEX($L$3:$L$12,MATCH(LARGE($R$3:$R$12,4),$R$3:$R$12,0))} -> Hidraulica | M41: =ROUND(LARGE($R$3:$R$12,4)/1000,0) -> 0 | N41: =IFERROR(SUM($M$38:M41)/SUM($M$3:$M$12)*100,0) -> 0.0
L42: {=INDEX($L$3:$L$12,MATCH(LARGE($R$3:$R$12,5),$R$3:$R$12,0))} -> Costura | M42: =ROUND(LARGE($R$3:$R$12,5)/1000,0) -> 0 | N42: =IFERROR(SUM($M$38:M42)/SUM($M$3:$M$12)*100,0) -> 0.0
L43: {=INDEX($L$3:$L$12,MATCH(LARGE($R$3:$R$12,6),$R$3:$R$12,0))} -> Montagem | M43: =ROUND(LARGE($R$3:$R$12,6)/1000,0) -> 0 | N43: =IFERROR(SUM($M$38:M43)/SUM($M$3:$M$12)*100,0) -> 0.0
L44: {=INDEX($L$3:$L$12,MATCH(LARGE($R$3:$R$12,7),$R$3:$R$12,0))} -> Peca faltante | M44: =ROUND(LARGE($R$3:$R$12,7)/1000,0) -> 0 | N44: =IFERROR(SUM($M$38:M44)/SUM($M$3:$M$12)*100,0) -> 0.0
L45: {=INDEX($L$3:$L$12,MATCH(LARGE($R$3:$R$12,8),$R$3:$R$12,0))} -> Peca quebrada | M45: =ROUND(LARGE($R$3:$R$12,8)/1000,0) -> 0 | N45: =IFERROR(SUM($M$38:M45)/SUM($M$3:$M$12)*100,0) -> 0.0
L46: {=INDEX($L$3:$L$12,MATCH(LARGE($R$3:$R$12,9),$R$3:$R$12,0))} -> Dificuldade de montagem | M46: =ROUND(LARGE($R$3:$R$12,9)/1000,0) -> 0 | N46: =IFERROR(SUM($M$38:M46)/SUM($M$3:$M$12)*100,0) -> 0.0
L47: {=INDEX($L$3:$L$12,MATCH(LARGE($R$3:$R$12,10),$R$3:$R$12,0))} -> Outros | M47: =ROUND(LARGE($R$3:$R$12,10)/1000,0) -> 0 | N47: =IFERROR(SUM($M$38:M47)/SUM($M$3:$M$12)*100,0) -> 0.0

Sheet TROCAS-DEVOLUCOES
A1: ID chamado (SAC) | B1: Data solicitacao | C1: Cliente | D1: Produto | E1: Tipo | F1: Motivo | G1: Peca faltante? | H1: Status | I1: Custo (R$) | J1: Data conclusao | K1: Dias para conclusao | M1: RESUMO - TIPO
A2: 1 | B2: 46266 | C2: Salao Bela Vida | D2: Cadeira de cabelo | E2: Troca de peca | F2: Pistao com vazamento | G2: Sim | H2: Em andamento | I2: 0 | K2: =IF(J2="","",J2-B2) | M2: Tipo | N2: Qtd
K3: =IF(J3="","",J3-B3) | M3: Troca de peca | N3: =COUNTIF(E3:E150,M3) -> 0
K4: =IF(J4="","",J4-B4) | M4: Troca do produto | N4: =COUNTIF(E3:E150,M4) -> 0
K5: =IF(J5="","",J5-B5) | M5: Devolucao total | N5: =COUNTIF(E3:E150,M5) -> 0
K6: =IF(J6="","",J6-B6) | M6: Devolucao parcial | N6: =COUNTIF(E3:E150,M6) -> 0
K7: =IF(J7="","",J7-B7)
K8: =IF(J8="","",J8-B8)
K9: =IF(J9="","",J9-B9)
K10: =IF(J10="","",J10-B10)
K11: =IF(J11="","",J11-B11)
K12: =IF(J12="","",J12-B12)
K13: =IF(J13="","",J13-B13)
K14: =IF(J14="","",J14-B14)
K15: =IF(J15="","",J15-B15)
K16: =IF(J16="","",J16-B16)
K17: =IF(J17="","",J17-B17)
K18: =IF(J18="","",J18-B18)
... K150: =IF(J150="","",J150-B150)

Sheet CLIENTES E RECOMPRA
A1: Cliente | B1: Contato | C1: Primeira compra | D1: Ultima compra | E1: N de compras | F1: Valor total (R$) | G1: Ja recomprou? | H1: Proxima recompra prevista | I1: Status do relacionamento | J1: Observacoes | L1: RESUMO - RELACIONAMENTO
A2: Salao Bela Vida | B2: (11) 90000-0000 | C2: 45726 | D2: 46266 | E2: 3 | F2: 15800 | G2: Sim | H2: 46388 | I2: Ativo | J2: Cliente fidelizado, indicou 2 novos | L2: Status | M2: Qtd
L3: Ativo | M3: =COUNTIF(I3:I150,L3) -> 0
L4: Em risco | M4: =COUNTIF(I3:I150,L4) -> 0
L5: Inativo | M5: =COUNTIF(I3:I150,L5) -> 0
L6: VIP | M6: =COUNTIF(I3:I150,L6) -> 0

Sheet PLANO DE ACAO
A1: Data | B1: Problema / Acao | C1: Origem (ID chamado) | D1: Responsavel | E1: Prazo | F1: Prioridade | G1: Status | H1: Resultado esperado | J1: RESUMO - STATUS DAS ACOES
A2: 46266 | B2: Padronizar embalagem das cadeiras para evitar avarias no transporte | C2: 1 | D2: Carlos | E2: 46295 | F2: Alta | G2: Em andamento | H2: Reduzir avarias de transporte em 50% no proximo trimestre | J2: Status | K2: Qtd
J3: Nao iniciado | K3: =COUNTIF(G3:G100,J3) -> 0
J4: Em andamento | K4: =COUNTIF(G3:G100,J4) -> 0
J5: Concluido | K5: =COUNTIF(G3:G100,J5) -> 0
J6: Atrasado | K6: =COUNTIF(G3:G100,J6) -> 0

Sheet LISTAS
A1: STATUS_CHAMADO | B1: PRIORIDADE | C1: CAUSA | D1: TIPO_CHAMADO | E1: CANAL | F1: CATEGORIA_PRODUTO | G1: SIM_NAO | H1: STATUS_ACAO | I1: FALHA_EMBALAGEM | J1: CAUSA_PROVAVEL | K1: SETOR_RESPONSAVEL
A2: Aberto | B2: Alta | C2: Acabamento | D2: Reclamacao | E2: Telefone | F2: Cadeira de cabelo | G2: Sim | H2: Nao iniciado | I2: Sem protecao/calco interno | J2: Fornecedor | K2: Producao
A3: Em andamento | B3: Media | C3: Embalagem | D3: Troca | E3: WhatsApp | F3: Lavatorio/Shampoo | G3: Nao | H3: Em andamento | I3: Caixa amassada ou papelao fino | J3: Producao interna | K3: Qualidade
A4: Aguardando cliente | B4: Baixa | C4: Material | D4: Devolucao | E4: E-mail | F4: Carrinho auxiliar | H4: Concluido | I4: Falta fita de reforco | J4: Transporte/Transportadora | K4: Logistica/Expedicao
A5: Resolvido | C5: Hidraulica | D5: Peca faltante | E5: Site | F5: Espelho/Estacao | H5: Atrasado | I5: Sem plastico bolha/espuma | J5: Projeto/Design | K5: Compras/Fornecedor
A6: Cancelado | C6: Costura | D6: Avaria | E6: Loja fisica | F6: Recepcao/Sofa | I6: Caixa subdimensionada para o produto | J6: Uso inadequado pelo cliente | K6: Comercial/Atendimento
C7: Montagem | D7: Duvida tecnica | E7: Rede social | F7: Maca | I7: Etiqueta de fragil ausente | J7: Erro operacional | K7: Design/Engenharia
C8: Peca faltante | D8: Elogio | F8: Outro | I8: Fixacao/paletizacao inadequada | J8: Outro | K8: Outro
C9: Peca quebrada | D9: Outro | I9: Outros
C10: Dificuldade de montagem
A11: Estas listas alimentam os menus suspensos das outras abas. Adicione itens nas celulas abaixo dos titulos se precisar. | C11: Outros
